Workbook
Name AR5_Ratio: [1]Lookups!$J$33:$K$37
Name AR5_TruFal: [1]Lookups!$G$33:$H$73

Sheet Information and Variables
B2: GHG Conversion Factors
B3: Reporting Year | C3: Resource | D3: tCO2e / kWh
B4: 2023/24 | C4: Electricity | D4: ='UK electricity 23'!E24/1000 -> 0.00020707429
C5: Natural Gas | D5: ='Fuels 23'!D42/1000 -> 0.00018292893
B6: 2024/25 | C6: Electricity | D6: ='UK electricity 24'!E25/1000 -> 0.00020705
C7: Natural Gas | D7: ='Fuels 24'!D42/1000 -> 0.0001829
B8: 2025/26 | C8: Electricity | D8: ='UK electricity 25'!E26/1000 -> 0.000177
C9: Natural Gas | D9: ='Fuels 25'!D42/1000 -> 0.00018296
B12: Financial factors
B13: Reporting Year | C13: Resource | D13: £ / kWh
B14: 2023/24 | C14: Electricity | D14: 0.28
C15: Natural Gas | D15: 0.08
B16: 2024/25 | C16: Electricity | D16: 0.26
C17: Natural Gas | D17: 0.075
B18: 2025/26 | C18: Electricity | D18: 0.25
C19: Natural Gas | D19: 0.065

Sheet Combined Site Table
A1: Month | B1: Financial Year | C1: Site | D1: Electricity (kWh) | E1: Electricity (tCO2e) | F1: Electricity Spend (£) | G1: Gas (kWh) | H1: Gas (tCO2e) | I1: Gas Spend (£)
A2: Apr-23 | B2: FY23/24 | C2: Site A | D2: 444337.32 | E2: =Site_Summary[[#This Row],[Electricity (kWh)]]*'Information and Variables'!$D$4 -> 92.010834 | F2: =Site_Summary[[#This Row],[Electricity (kWh)]]*'Information and Variables'!$D$14 -> 124414.45 | G2: 446053.72 | H2: =Site_Summary[[#This Row],[Gas (kWh)]]*'Information and Variables'!$D$5 -> 81.596128 | I2: =Site_Summary[[#This Row],[Gas (kWh)]]*'Information and Variables'!$D$15 -> 35684.298
A3: Apr-23 | B3: FY23/24 | C3: Site B | D3: 340707.47 | E3: =Site_Summary[[#This Row],[Electricity (kWh)]]*'Information and Variables'!$D$4 -> 70.551757 | F3: =Site_Summary[[#This Row],[Electricity (kWh)]]*'Information and Variables'!$D$14 -> 95398.092 | G3: 294275.02 | H3: =Site_Summary[[#This Row],[Gas (kWh)]]*'Information and Variables'!$D$5 -> 53.831413 | I3: =Site_Summary[[#This Row],[Gas (kWh)]]*'Information and Variables'!$D$15 -> 23542.002
A4: Apr-23 | B4: FY23/24 | C4: Site C | D4: 210951.87 | E4: =Site_Summary[[#This Row],[Electricity (kWh)]]*'Information and Variables'!$D$4 -> 43.682708 | F4: =Site_Summary[[#This Row],[Electricity (kWh)]]*'Information and Variables'!$D$14 -> 59066.524 | G4: 222240.25 | H4: =Site_Summary[[#This Row],[Gas (kWh)]]*'Information and Variables'!$D$5 -> 40.65417 | I4: =Site_Summary[[#This Row],[Gas (kWh)]]*'Information and Variables'!$D$15 -> 17779.22
A5: Apr-23 | B5: FY23/24 | C5: Site D | D5: 98532.56 | E5: =Site_Summary[[#This Row],[Electricity (kWh)]]*'Information and Variables'!$D$4 -> 20.40356 | F5: =Site_Summary[[#This Row],[Electricity (kWh)]]*'Information and Variables'!$D$14 -> 27589.117 | G5: 95581.08 | H5: =Site_Summary[[#This Row],[Gas (kWh)]]*'Information and Variables'!$D$5 -> 17.484544 | I5: =Site_Summary[[#This Row],[Gas (kWh)]]*'Information and Variables'!$D$15 -> 7646.4864
A6: May-23 | B6: FY23/24 | C6: Site A | D6: 395421.49 | E6: =Site_Summary[[#This Row],[Electricity (kWh)]]*'Information and Variables'!$D$4 -> 81.881624 | F6: =Site_Summary[[#This Row],[Electricity (kWh)]]*'Information and Variables'!$D$14 -> 110718.02 | G6: 339439.56 | H6: =Site_Summary[[#This Row],[Gas (kWh)]]*'Information and Variables'!$D$5 -> 62.093314 | I6: =Site_Summary[[#This Row],[Gas (kWh)]]*'Information and Variables'!$D$15 -> 27155.165
A7: May-23 | B7: FY23/24 | C7: Site B | D7: 306897.5 | E7: =Site_Summary[[#This Row],[Electricity (kWh)]]*'Information and Variables'!$D$4 -> 63.550581 | F7: =Site_Summary[[#This Row],[Electricity (kWh)]]*'Information and Variables'!$D$14 -> 85931.3 | G7: 218436.96 | H7: =Site_Summary[[#This Row],[Gas (kWh)]]*'Information and Variables'!$D$5 -> 39.958439 | I7: =Site_Summary[[#This Row],[Gas (kWh)]]*'Information and Variables'!$D$15 -> 17474.957
A8: May-23 | B8: FY23/24 | C8: Site C | D8: 216746.84 | E8: =Site_Summary[[#This Row],[Electricity (kWh)]]*'Information and Variables'!$D$4 -> 44.882698 | F8: =Site_Summary[[#This Row],[Electricity (kWh)]]*'Information and Variables'!$D$14 -> 60689.115 | G8: 181802.75 | H8: =Site_Summary[[#This Row],[Gas (kWh)]]*'Information and Variables'!$D$5 -> 33.256982 | I8: =Site_Summary[[#This Row],[Gas (kWh)]]*'Information and Variables'!$D$15 -> 14544.22
A9: May-23 | B9: FY23/24 | C9: Site D | D9: 106049.09 | E9: =Site_Summary[[#This Row],[Electricity (kWh)]]*'Information and Variables'!$D$4 -> 21.96004 | F9: =Site_Summary[[#This Row],[Electricity (kWh)]]*'Information and Variables'!$D$14 -> 29693.745 | G9: 82340.86 | H9: =Site_Summary[[#This Row],[Gas (kWh)]]*'Information and Variables'!$D$5 -> 15.062525 | I9: =Site_Summary[[#This Row],[Gas (kWh)]]*'Information and Variables'!$D$15 -> 6587.2688
A10: Jun-23 | B10: FY23/24 | C10: Site A | D10: 387104.17 | E10: =Site_Summary[[#This Row],[Electricity (kWh)]]*'Information and Variables'!$D$4 -> 80.159321 | F10: =Site_Summary[[#This Row],[Electricity (kWh)]]*'Information and Variables'!$D$14 -> 108389.17 | G10: 312971.58 | H10: =Site_Summary[[#This Row],[Gas (kWh)]]*'Information and Variables'!$D$5 -> 57.251555 | I10: =Site_Summary[[#This Row],[Gas (kWh)]]*'Information and Variables'!$D$15 -> 25037.726
A11: Jun-23 | B11: FY23/24 | C11: Site B | D11: 305632.29 | E11: =Site_Summary[[#This Row],[Electricity (kWh)]]*'Information and Variables'!$D$4 -> 63.288589 | F11: =Site_Summary[[#This Row],[Electricity (kWh)]]*'Information and Variables'!$D$14 -> 85577.041 | G11: 184767.82 | H11: =Site_Summary[[#This Row],[Gas (kWh)]]*'Information and Variables'!$D$5 -> 33.799379 | I11: =Site_Summary[[#This Row],[Gas (kWh)]]*'Information and Variables'!$D$15 -> 14781.426
A12: Jun-23 | B12: FY23/24 | C12: Site C | D12: 228579.68 | E12: =Site_Summary[[#This Row],[Electricity (kWh)]]*'Information and Variables'!$D$4 -> 47.332975 | F12: =Site_Summary[[#This Row],[Electricity (kWh)]]*'Information and Variables'!$D$14 -> 64002.31 | G12: 142706.65 | H12: =Site_Summary[[#This Row],[Gas (kWh)]]*'Information and Variables'!$D$5 -> 26.105174 | I12: =Site_Summary[[#This Row],[Gas (kWh)]]*'Information and Variables'!$D$15 -> 11416.532
A13: Jun-23 | B13: FY23/24 | C13: Site D | D13: 112128.81 | E13: =Site_Summary[[#This Row],[Electricity (kWh)]]*'Information and Variables'!$D$4 -> 23.218994 | F13: =Site_Summary[[#This Row],[Electricity (kWh)]]*'Information and Variables'!$D$14 -> 31396.067 | G13: 76813.43 | H13: =Site_Summary[[#This Row],[Gas (kWh)]]*'Information and Variables'!$D$5 -> 14.051398 | I13: =Site_Summary[[#This Row],[Gas (kWh)]]*'Information and Variables'!$D$15 -> 6145.0744
... A49: Mar-24 | B49: FY23/24 | C49: Site D | D49: 104494.85 | E49: =Site_Summary[[#This Row],[Electricity (kWh)]]*'Information and Variables'!$D$4 -> 21.638197 | F49: =Site_Summary[[#This Row],[Electricity (kWh)]]*'Information and Variables'!$D$14 -> 29258.558 | G49: 145680.5 | H49: =Site_Summary[[#This Row],[Gas (kWh)]]*'Information and Variables'!$D$5 -> 26.649177 | I49: =Site_Summary[[#This Row],[Gas (kWh)]]*'Information and Variables'!$D$15 -> 11654.44
A50: Apr-24 | B50: FY24/25 | C50: Site A | D50: 420135.12 | E50: =Site_Summary[[#This Row],[Electricity (kWh)]]*'Information and Variables'!$D$6 -> 86.988977 | F50: =Site_Summary[[#This Row],[Electricity (kWh)]]*'Information and Variables'!$D$16 -> 109235.13 | G50: 371835.29 | H50: =Site_Summary[[#This Row],[Gas (kWh)]]*'Information and Variables'!$D$7 -> 68.008675 | I50: =Site_Summary[[#This Row],[Gas (kWh)]]*'Information and Variables'!$D$17 -> 27887.647
A51: Apr-24 | B51: FY24/25 | C51: Site B | D51: 339988.49 | E51: =Site_Summary[[#This Row],[Electricity (kWh)]]*'Information and Variables'!$D$6 -> 70.394617 | F51: =Site_Summary[[#This Row],[Electricity (kWh)]]*'Information and Variables'!$D$16 -> 88397.007 | G51: 308737.72 | H51: =Site_Summary[[#This Row],[Gas (kWh)]]*'Information and Variables'!$D$7 -> 56.468129 | I51: =Site_Summary[[#This Row],[Gas (kWh)]]*'Information and Variables'!$D$17 -> 23155.329
A52: Apr-24 | B52: FY24/25 | C52: Site C | D52: 220187.43 | E52: =Site_Summary[[#This Row],[Electricity (kWh)]]*'Information and Variables'!$D$6 -> 45.589807 | F52: =Site_Summary[[#This Row],[Electricity (kWh)]]*'Information and Variables'!$D$16 -> 57248.732 | G52: 223237.79 | H52: =Site_Summary[[#This Row],[Gas (kWh)]]*'Information and Variables'!$D$7 -> 40.830192 | I52: =Site_Summary[[#This Row],[Gas (kWh)]]*'Information and Variables'!$D$17 -> 16742.834
A53: Apr-24 | B53: FY24/25 | C53: Site D | D53: 102385.12 | E53: =Site_Summary[[#This Row],[Electricity (kWh)]]*'Information and Variables'!$D$6 -> 21.198839 | F53: =Site_Summary[[#This Row],[Electricity (kWh)]]*'Information and Variables'!$D$16 -> 26620.131 | G53: 110400.92 | H53: =Site_Summary[[#This Row],[Gas (kWh)]]*'Information and Variables'!$D$7 -> 20.192328 | I53: =Site_Summary[[#This Row],[Gas (kWh)]]*'Information and Variables'!$D$17 -> 8280.069
A54: May-24 | B54: FY24/25 | C54: Site A | D54: 421383.4 | E54: =Site_Summary[[#This Row],[Electricity (kWh)]]*'Information and Variables'!$D$6 -> 87.247433 | F54: =Site_Summary[[#This Row],[Electricity (kWh)]]*'Information and Variables'!$D$16 -> 109559.68 | G54: 318318.97 | H54: =Site_Summary[[#This Row],[Gas (kWh)]]*'Information and Variables'!$D$7 -> 58.22054 | I54: =Site_Summary[[#This Row],[Gas (kWh)]]*'Information and Variables'!$D$17 -> 23873.923
A55: May-24 | B55: FY24/25 | C55: Site B | D55: 327415.8 | E55: =Site_Summary[[#This Row],[Electricity (kWh)]]*'Information and Variables'!$D$6 -> 67.791441 | F55: =Site_Summary[[#This Row],[Electricity (kWh)]]*'Information and Variables'!$D$16 -> 85128.108 | G55: 224062.5 | H55: =Site_Summary[[#This Row],[Gas (kWh)]]*'Information and Variables'!$D$7 -> 40.981031 | I55: =Site_Summary[[#This Row],[Gas (kWh)]]*'Information and Variables'!$D$17 -> 16804.688
A56: May-24 | B56: FY24/25 | C56: Site C | D56: 246069.75 | E56: =Site_Summary[[#This Row],[Electricity (kWh)]]*'Information and Variables'!$D$6 -> 50.948742 | F56: =Site_Summary[[#This Row],[Electricity (kWh)]]*'Information and Variables'!$D$16 -> 63978.135 | G56: 182253.77 | H56: =Site_Summary[[#This Row],[Gas (kWh)]]*'Information and Variables'!$D$7 -> 33.334215 | I56: =Site_Summary[[#This Row],[Gas (kWh)]]*'Information and Variables'!$D$17 -> 13669.033
A57: May-24 | B57: FY24/25 | C57: Site D | D57: 118653.66 | E57: =Site_Summary[[#This Row],[Electricity (kWh)]]*'Information and Variables'!$D$6 -> 24.56724 | F57: =Site_Summary[[#This Row],[Electricity (kWh)]]*'Information and Variables'!$D$16 -> 30849.952 | G57: 96078.73 | H57: =Site_Summary[[#This Row],[Gas (kWh)]]*'Information and Variables'!$D$7 -> 17.5728 | I57: =Site_Summary[[#This Row],[Gas (kWh)]]*'Information and Variables'!$D$17 -> 7205.9047
A58: Jun-24 | B58: FY24/25 | C58: Site A | D58: 376626.54 | E58: =Site_Summary[[#This Row],[Electricity (kWh)]]*'Information and Variables'!$D$6 -> 77.980525 | F58: =Site_Summary[[#This Row],[Electricity (kWh)]]*'Information and Variables'!$D$16 -> 97922.9 | G58: 297094.47 | H58: =Site_Summary[[#This Row],[Gas (kWh)]]*'Information and Variables'!$D$7 -> 54.338579 | I58: =Site_Summary[[#This Row],[Gas (kWh)]]*'Information and Variables'!$D$17 -> 22282.085
A59: Jun-24 | B59: FY24/25 | C59: Site B | D59: 331636.12 | E59: =Site_Summary[[#This Row],[Electricity (kWh)]]*'Information and Variables'!$D$6 -> 68.665259 | F59: =Site_Summary[[#This Row],[Electricity (kWh)]]*'Information and Variables'!$D$16 -> 86225.391 | G59: 182549.18 | H59: =Site_Summary[[#This Row],[Gas (kWh)]]*'Information and Variables'!$D$7 -> 33.388245 | I59: =Site_Summary[[#This Row],[Gas (kWh)]]*'Information and Variables'!$D$17 -> 13691.188
A60: Jun-24 | B60: FY24/25 | C60: Site C | D60: 232761.54 | E60: =Site_Summary[[#This Row],[Electricity (kWh)]]*'Information and Variables'!$D$6 -> 48.193277 | F60: =Site_Summary[[#This Row],[Electricity (kWh)]]*'Information and Variables'!$D$16 -> 60518 | G60: 136765.36 | H60: =Site_Summary[[#This Row],[Gas (kWh)]]*'Information and Variables'!$D$7 -> 25.014384 | I60: =Site_Summary[[#This Row],[Gas (kWh)]]*'Information and Variables'!$D$17 -> 10257.402
A61: Jun-24 | B61: FY24/25 | C61: Site D | D61: 114674.01 | E61: =Site_Summary[[#This Row],[Electricity (kWh)]]*'Information and Variables'!$D$6 -> 23.743254 | F61: =Site_Summary[[#This Row],[Electricity (kWh)]]*'Information and Variables'!$D$16 -> 29815.243 | G61: 76301.49 | H61: =Site_Summary[[#This Row],[Gas (kWh)]]*'Information and Variables'!$D$7 -> 13.955543 | I61: =Site_Summary[[#This Row],[Gas (kWh)]]*'Information and Variables'!$D$17 -> 5722.6118
... A97: Mar-25 | B97: FY24/25 | C97: Site D | D97: 112054.07 | E97: =Site_Summary[[#This Row],[Electricity (kWh)]]*'Information and Variables'!$D$6 -> 23.200795 | F97: =Site_Summary[[#This Row],[Electricity (kWh)]]*'Information and Variables'!$D$16 -> 29134.058 | G97: 149682.94 | H97: =Site_Summary[[#This Row],[Gas (kWh)]]*'Information and Variables'!$D$7 -> 27.37701 | I97: =Site_Summary[[#This Row],[Gas (kWh)]]*'Information and Variables'!$D$17 -> 11226.22
A98: Apr-25 | B98: FY25/26 | C98: Site A | D98: 472886.56 | E98: =Site_Summary[[#This Row],[Electricity (kWh)]]*'Information and Variables'!$D$8 -> 83.700921 | F98: =Site_Summary[[#This Row],[Electricity (kWh)]]*'Information and Variables'!$D$18 -> 118221.64 | G98: 470373.97 | H98: =Site_Summary[[#This Row],[Gas (kWh)]]*'Information and Variables'!$D$9 -> 86.059622 | I98: =Site_Summary[[#This Row],[Gas (kWh)]]*'Information and Variables'!$D$19 -> 30574.308
A99: Apr-25 | B99: FY25/26 | C99: Site B | D99: 296323.13 | E99: =Site_Summary[[#This Row],[Electricity (kWh)]]*'Information and Variables'!$D$8 -> 52.449194 | F99: =Site_Summary[[#This Row],[Electricity (kWh)]]*'Information and Variables'!$D$18 -> 74080.783 | G99: 282898.32 | H99: =Site_Summary[[#This Row],[Gas (kWh)]]*'Information and Variables'!$D$9 -> 51.759077 | I99: =Site_Summary[[#This Row],[Gas (kWh)]]*'Information and Variables'!$D$19 -> 18388.391
A100: Apr-25 | B100: FY25/26 | C100: Site C | D100: 201453.37 | E100: =Site_Summary[[#This Row],[Electricity (kWh)]]*'Information and Variables'!$D$8 -> 35.657246 | F100: =Site_Summary[[#This Row],[Electricity (kWh)]]*'Information and Variables'!$D$18 -> 50363.342 | G100: 200333.2 | H100: =Site_Summary[[#This Row],[Gas (kWh)]]*'Information and Variables'!$D$9 -> 36.652962 | I100: =Site_Summary[[#This Row],[Gas (kWh)]]*'Information and Variables'!$D$19 -> 13021.658
A101: Apr-25 | B101: FY25/26 | C101: Site D | D101: 103137.55 | E101: =Site_Summary[[#This Row],[Electricity (kWh)]]*'Information and Variables'!$D$8 -> 18.255346 | F101: =Site_Summary[[#This Row],[Electricity (kWh)]]*'Information and Variables'!$D$18 -> 25784.388 | G101: 104561.6 | H101: =Site_Summary[[#This Row],[Gas (kWh)]]*'Information and Variables'!$D$9 -> 19.13059 | I101: =Site_Summary[[#This Row],[Gas (kWh)]]*'Information and Variables'!$D$19 -> 6796.504
A102: May-25 | B102: FY25/26 | C102: Site A | D102: 425633.39 | E102: =Site_Summary[[#This Row],[Electricity (kWh)]]*'Information and Variables'!$D$8 -> 75.33711 | F102: =Site_Summary[[#This Row],[Electricity (kWh)]]*'Information and Variables'!$D$18 -> 106408.35 | G102: 339499.47 | H102: =Site_Summary[[#This Row],[Gas (kWh)]]*'Information and Variables'!$D$9 -> 62.114823 | I102: =Site_Summary[[#This Row],[Gas (kWh)]]*'Information and Variables'!$D$19 -> 22067.466
A103: May-25 | B103: FY25/26 | C103: Site B | D103: 349114.08 | E103: =Site_Summary[[#This Row],[Electricity (kWh)]]*'Information and Variables'!$D$8 -> 61.793192 | F103: =Site_Summary[[#This Row],[Electricity (kWh)]]*'Information and Variables'!$D$18 -> 87278.52 | G103: 235046.25 | H103: =Site_Summary[[#This Row],[Gas (kWh)]]*'Information and Variables'!$D$9 -> 43.004062 | I103: =Site_Summary[[#This Row],[Gas (kWh)]]*'Information and Variables'!$D$19 -> 15278.006
A104: May-25 | B104: FY25/26 | C104: Site C | D104: 205572.32 | E104: =Site_Summary[[#This Row],[Electricity (kWh)]]*'Information and Variables'!$D$8 -> 36.386301 | F104: =Site_Summary[[#This Row],[Electricity (kWh)]]*'Information and Variables'!$D$18 -> 51393.08 | G104: 151907.91 | H104: =Site_Summary[[#This Row],[Gas (kWh)]]*'Information and Variables'!$D$9 -> 27.793071 | I104: =Site_Summary[[#This Row],[Gas (kWh)]]*'Information and Variables'!$D$19 -> 9874.0142
A105: May-25 | B105: FY25/26 | C105: Site D | D105: 97620.53 | E105: =Site_Summary[[#This Row],[Electricity (kWh)]]*'Information and Variables'!$D$8 -> 17.278834 | F105: =Site_Summary[[#This Row],[Electricity (kWh)]]*'Information and Variables'!$D$18 -> 24405.132 | G105: 77661.22 | H105: =Site_Summary[[#This Row],[Gas (kWh)]]*'Information and Variables'!$D$9 -> 14.208897 | I105: =Site_Summary[[#This Row],[Gas (kWh)]]*'Information and Variables'!$D$19 -> 5047.9793
A106: Jun-25 | B106: FY25/26 | C106: Site A | D106: 421620.06 | E106: =Site_Summary[[#This Row],[Electricity (kWh)]]*'Information and Variables'!$D$8 -> 74.626751 | F106: =Site_Summary[[#This Row],[Electricity (kWh)]]*'Information and Variables'!$D$18 -> 105405.01 | G106: 279080.59 | H106: =Site_Summary[[#This Row],[Gas (kWh)]]*'Information and Variables'!$D$9 -> 51.060585 | I106: =Site_Summary[[#This Row],[Gas (kWh)]]*'Information and Variables'!$D$19 -> 18140.238
A107: Jun-25 | B107: FY25/26 | C107: Site B | D107: 321910.62 | E107: =Site_Summary[[#This Row],[Electricity (kWh)]]*'Information and Variables'!$D$8 -> 56.97818 | F107: =Site_Summary[[#This Row],[Electricity (kWh)]]*'Information and Variables'!$D$18 -> 80477.655 | G107: 202844.48 | H107: =Site_Summary[[#This Row],[Gas (kWh)]]*'Information and Variables'!$D$9 -> 37.112426 | I107: =Site_Summary[[#This Row],[Gas (kWh)]]*'Information and Variables'!$D$19 -> 13184.891
A108: Jun-25 | B108: FY25/26 | C108: Site C | D108: 207975.13 | E108: =Site_Summary[[#This Row],[Electricity (kWh)]]*'Information and Variables'!$D$8 -> 36.811598 | F108: =Site_Summary[[#This Row],[Electricity (kWh)]]*'Information and Variables'!$D$18 -> 51993.783 | G108: 121860.22 | H108: =Site_Summary[[#This Row],[Gas (kWh)]]*'Information and Variables'!$D$9 -> 22.295546 | I108: =Site_Summary[[#This Row],[Gas (kWh)]]*'Information and Variables'!$D$19 -> 7920.9143
A109: Jun-25 | B109: FY25/26 | C109: Site D | D109: 114688.24 | E109: =Site_Summary[[#This Row],[Electricity (kWh)]]*'Information and Variables'!$D$8 -> 20.299818 | F109: =Site_Summary[[#This Row],[Electricity (kWh)]]*'Information and Variables'!$D$18 -> 28672.06 | G109: 66549.59 | H109: =Site_Summary[[#This Row],[Gas (kWh)]]*'Information and Variables'!$D$9 -> 12.175913 | I109: =Site_Summary[[#This Row],[Gas (kWh)]]*'Information and Variables'!$D$19 -> 4325.7234
... A145: Mar-26 | B145: FY25/26 | C145: Site D | D145: 106422.02 | E145: =Site_Summary[[#This Row],[Electricity (kWh)]]*'Information and Variables'!$D$8 -> 18.836698 | F145: =Site_Summary[[#This Row],[Electricity (kWh)]]*'Information and Variables'!$D$18 -> 26605.505 | G145: 141056.69 | H145: =Site_Summary[[#This Row],[Gas (kWh)]]*'Information and Variables'!$D$9 -> 25.807732 | I145: =Site_Summary[[#This Row],[Gas (kWh)]]*'Information and Variables'!$D$19 -> 9168.6848

Sheet EGLC_HDD_18.5C
A1: Description: | B1: Celsius-based heating degree days with a base temperature of 18.5 C
A2: Source: | B2: www.degreedays.net
A3: Accuracy: | B3: Estimates were made to account for missing data: the "% Estimated" column shows how much each figure was affected (0% is best, 100% is worst)
A4: Station: | B4: London City Airport (0.06E,51.51N)
A5: Station ID: | B5: EGLC
A7: Month starting | B7: HDD 18.5 | C7: % Estimated
A8: 45017 | B8: 210.2 | C8: 0
A9: 45047 | B9: 122.2 | C9: 0
A10: 45078 | B10: 50.7 | C10: 0.1
A11: 45108 | B11: 34 | C11: 0
A12: 45139 | B12: 38.4 | C12: 0
A13: 45170 | B13: 36.2 | C13: 0
A14: 45200 | B14: 139.4 | C14: 0
A15: 45231 | B15: 288.2 | C15: 0
A16: 45261 | B16: 300.4 | C16: 0
A17: 45292 | B17: 381.5 | C17: 0
A18: 45323 | B18: 259.9 | C18: 0
A19: 45352 | B19: 275.8 | C19: 0
... A43: 46082 | B43: 281.2 | C43: 0

Sheet Site A
A1: Site Name | B1: Date | C1: Electricity (kWh) | D1: Gas (kWh)
A2: Site A | B2: Apr-23 | C2: 444337.32 | D2: 446053.72
A3: Site A | B3: May-23 | C3: 395421.49 | D3: 339439.56
A4: Site A | B4: Jun-23 | C4: 387104.17 | D4: 312971.58
A5: Site A | B5: Jul-23 | C5: 433222.17 | D5: 303750.51
A6: Site A | B6: Aug-23 | C6: 383919.48 | D6: 319021.65
A7: Site A | B7: Sep-23 | C7: 452868.12 | D7: 343547.29
A8: Site A | B8: Oct-23 | C8: 397613.14 | D8: 546300.56
A9: Site A | B9: Nov-23 | C9: 408009.67 | D9: 879176.87
A10: Site A | B10: Dec-23 | C10: 418855.08 | D10: 1257475.2
A11: Site A | B11: Jan-24 | C11: 434134.11 | D11: 1352946.4
A12: Site A | B12: Feb-24 | C12: 406982.26 | D12: 1064328.4
A13: Site A | B13: Mar-24 | C13: 420903.94 | D13: 693556.67
... A37: Site A | B37: Mar-26 | C37: 488968.58 | D37: 595230.95

Sheet Site B
A1: Site Name | B1: Date | C1: Electricity (kWh) | D1: Gas (kWh)
A2: Site B | B2: Apr-23 | C2: 340707.47 | D2: 294275.02
A3: Site B | B3: May-23 | C3: 306897.5 | D3: 218436.96
A4: Site B | B4: Jun-23 | C4: 305632.29 | D4: 184767.82
A5: Site B | B5: Jul-23 | C5: 332226.65 | D5: 196729.37
A6: Site B | B6: Aug-23 | C6: 342239.09 | D6: 190398.01
A7: Site B | B7: Sep-23 | C7: 293473.78 | D7: 249534.52
A8: Site B | B8: Oct-23 | C8: 334207.38 | D8: 387616.83
A9: Site B | B9: Nov-23 | C9: 334854.23 | D9: 573673.15
A10: Site B | B10: Dec-23 | C10: 319084.39 | D10: 849093.02
A11: Site B | B11: Jan-24 | C11: 287491.02 | D11: 882235.95
A12: Site B | B12: Feb-24 | C12: 287872.83 | D12: 737570.43
A13: Site B | B13: Mar-24 | C13: 305846.62 | D13: 431527.86
... A37: Site B | B37: Mar-26 | C37: 351855.51 | D37: 415965.12

Sheet Site C
A1: Site Name | B1: Date | C1: Electricity (kWh) | D1: Gas (kWh)
A2: Site C | B2: Apr-23 | C2: 210951.87 | D2: 222240.25
A3: Site C | B3: May-23 | C3: 216746.84 | D3: 181802.75
A4: Site C | B4: Jun-23 | C4: 228579.68 | D4: 142706.65
A5: Site C | B5: Jul-23 | C5: 204390.94 | D5: 151194.84
A6: Site C | B6: Aug-23 | C6: 214653.94 | D6: 132809.23
A7: Site C | B7: Sep-23 | C7: 202186.22 | D7: 180335.77
A8: Site C | B8: Oct-23 | C8: 230540.41 | D8: 255987.27
A9: Site C | B9: Nov-23 | C9: 223172.5 | D9: 401826.37
A10: Site C | B10: Dec-23 | C10: 229098.11 | D10: 596091.84
A11: Site C | B11: Jan-24 | C11: 231135.88 | D11: 692415.42
A12: Site C | B12: Feb-24 | C12: 242080.22 | D12: 492827.64
A13: Site C | B13: Mar-24 | C13: 215557.22 | D13: 294163.28
... A37: Site C | B37: Mar-26 | C37: 202577.4 | D37: 288960.1

Sheet Site D
A1: Site Name | B1: Date | C1: Electricity (kWh) | D1: Gas (kWh)
A2: Site D | B2: Apr-23 | C2: 98532.56 | D2: 95581.08
A3: Site D | B3: May-23 | C3: 106049.09 | D3: 82340.86
A4: Site D | B4: Jun-23 | C4: 112128.81 | D4: 76813.43
A5: Site D | B5: Jul-23 | C5: 111601.31 | D5: 68591.59
A6: Site D | B6: Aug-23 | C6: 93064.35 | D6: 76452.74
A7: Site D | B7: Sep-23 | C7: 101570.74 | D7: 96240.84
A8: Site D | B8: Oct-23 | C8: 112606.17 | D8: 150784.17
A9: Site D | B9: Nov-23 | C9: 98814.43 | D9: 206405.97
A10: Site D | B10: Dec-23 | C10: 110287.87 | D10: 305288.09
A11: Site D | B11: Jan-24 | C11: 96239.07 | D11: 356101.36
A12: Site D | B12: Feb-24 | C12: 112040.1 | D12: 274429.4
A13: Site D | B13: Mar-24 | C13: 104494.85 | D13: 145680.5
... A37: Site D | B37: Mar-26 | C37: 106422.02 | D37: 141056.69

Sheet Fuels 23
A1: UK Government GHG Conversion Factors for Company Reporting
A2: Fuels
A3: Index
A5: Emissions source: | B5: Fuels | C5: Next publication date: | D5: 45453 | E5: Factor set: | F5: Condensed set
A6: Scope: | B6: Scope 1 | C6: Version: | D6: 1.1 | E6: Year: | F6: 2023
A8: Fuels conversion factors should be used for primary fuel sources combusted at a site or in an asset owned or controlled by the reporting organisation.
A10: Guidance
A11: ● Gross calorific value (CV)/ net CV basis - Organisations should determine whether to use the net or gross calorific value of fuels according to their data. For example, the majority of energy billing is provided on a gross CV basis.
A12: ● 'Diesel (average biofuel blend)'/'diesel (100% mineral oil)' - typically organisations purchasing forecourt fuel should use 'diesel (average biofuel blend)'. It should be noted that any fuel an organisation reports in Scope 1 that has biofuel content must have the ‘outside of scopes’ portion reported separately as per the 'WBCSD/WRI GHG Protocol (chapter 9)'. See information about the outside of scopes emissions in the example section below. ● In 2019 update, a new factor for natural gas, "natural gas (100% mineral blend)", was added in. The difference between the "natural gas" and "natural gas (100% mineral blend)" factors is that the former refers to the natural gas received through the gas mains grid network in the UK containing a limited biogas content. Therefore, any organisation that reports emissions from natural gas use should use the "natural gas" factor. The natural gas (100% mineral blend) factor can be used for calculating bespoke fuel mixtures.
A13: ● If any fuel type or unit has no result in the table, this is an indication the conversion factor is not available or does not exist. ● Users of the aviation turbine fuel factors may need to apply a 1.7 multiplier to the CO2 factor to account for the radiative forcing effects of emissions at altitude. Further explanation of this is provided in the Conversion Factors Methodology Paper.
A14: Example of calculating emissions from fuels
A15: Company A needs to report the Scope 1 emissions from its natural gas and diesel use.
A16: ● For natural gas consumption it selects a kWh conversion factor on a gross CV basis - this is the basis of most energy bills. It reports in CO2e for all fuels combusted at its premises.
A17: ● It is faced with two different types of diesel conversion factors, '100% mineral fuel' and 'diesel (average biofuel blend)'. Since it fills up its vehicles at a national chain of filling stations, it selects the average biofuel blend (this is the correct conversion factor for standard forecourt fuel, which contains a small blend of biofuel).
A18: The activity data (that is, litres) is multiplied by the appropriate conversion factor to produce company A's fuel emissions. Organisations should determine whether to use the net or gross calorific value of fuels according to their data. For example, the majority of energy billing is provided on a gross CV basis.
A19: Since company A is reporting a type of fuel that has biofuel content, it should also account for the ‘biogenic’ part of this fuel. To calculate this, it must also multiply the total litres of fuel used by the ‘outside of scopes’ fuel factor for ‘forecourt fuels- diesel (average biofuel blend)’ and report as a separate line item within its report called ‘outside of scopes’. This will not be included in the organisation's emissions total, but displayed separately within the emissions report. This ensures that the organisation is being transparent with regard to all potential sources of CO2 from its activities.
A20: For more information refer to the ‘Outside of scopes’ tab for guidance.
A22: Activity | B22: Fuel | C22: Unit | D22: kg CO2e | E22: kg CO2e of CO2 per unit | F22: kg CO2e of CH4 per unit | G22: kg CO2e of N2O per unit
A23: Gaseous fuels | B23: Butane | C23: tonnes | D23: 3033.3807 | E23: 3029.26 | F23: 2.52 | G23: 1.6006711
B24: Butane | C24: litres | D24: 1.7453296 | E24: 1.74296 | F24: 0.0014448 | G24: 0.00092483221
B25: Butane | C25: kWh (Net CV) | D25: 0.2410661 | E25: 0.24074 | F25: 0.0002016 | G25: 0.00012449664
B26: Butane | C26: kWh (Gross CV) | D26: 0.222406 | E26: 0.2221 | F26: 0.0001904 | G26: 0.00011560403
B27: CNG | C27: tonnes | D27: 2562.5744 | E27: 2557.53 | F27: 3.8528 | G27: 1.1916107
C28: litres | D28: 0.44844653 | E28: 0.44757 | F28: 0.000672 | G28: 0.0002045302
C29: kWh (Net CV) | D29: 0.20267142 | E29: 0.20226 | F29: 0.0003136 | G29: 9.7818792e-05
C30: kWh (Gross CV) | D30: 0.18292893 | E30: 0.18256 | F30: 0.00028 | G30: 8.8926174e-05
B31: LNG | C31: tonnes | D31: 2581.9844 | E31: 2576.94 | F31: 3.8528 | G31: 1.1916107
C32: litres | D32: 1.1683296 | E32: 1.16604 | F32: 0.0017472 | G32: 0.00054244966
C33: kWh (Net CV) | D33: 0.20420142 | E33: 0.20379 | F33: 0.0003136 | G33: 9.7818792e-05
C34: kWh (Gross CV) | D34: 0.18431893 | E34: 0.18395 | F34: 0.00028 | G34: 8.8926174e-05
B35: LPG | C35: tonnes | D35: 2939.3609 | E35: 2935.18 | F35: 2.5536 | G35: 1.627349
C36: litres | D36: 1.5571278 | E36: 1.55491 | F36: 0.0013552 | G36: 0.00086258389
C37: kWh (Net CV) | D37: 0.2303161 | E37: 0.22999 | F37: 0.0002016 | G37: 0.00012449664
C38: kWh (Gross CV) | D38: 0.214496 | E38: 0.21419 | F38: 0.0001904 | G38: 0.00011560403
B39: Natural gas | C39: tonnes | D39: 2562.5744 | E39: 2557.53 | F39: 3.8528 | G39: 1.1916107
C40: cubic metres | D40: 2.0383903 | E40: 2.03437 | F40: 0.0030688 | G40: 0.00095151007
C41: kWh (Net CV) | D41: 0.20267142 | E41: 0.20226 | F41: 0.0003136 | G41: 9.7818792e-05
C42: kWh (Gross CV) | D42: 0.18292893 | E42: 0.18256 | F42: 0.00028 | G42: 8.8926174e-05
B43: Natural gas (100% mineral blend) | C43: tonnes | D43: 2581.9844 | E43: 2576.94 | F43: 3.8528 | G43: 1.1916107
C44: cubic metres | D44: 2.0538303 | E44: 2.04981 | F44: 0.0030688 | G44: 0.00095151007
...

Sheet Fuels 24
A1: UK Government GHG Conversion Factors for Company Reporting
A2: Fuels
A3: Index
A5: Emissions source: | B5: Fuels | C5: Next publication date: | D5: 45818 | E5: Factor set: | F5: Condensed set
A6: Scope: | B6: Scope 1 | C6: Version: | D6: 1.1 | E6: Year: | F6: 2024
A8: Fuels conversion factors should be used for primary fuel sources combusted at a site or in an asset owned or controlled by the reporting organisation.
A10: Guidance
A11: ● Gross calorific value (CV)/ net CV basis: - Organisations should determine whether to use the net or gross calorific value of fuels according to their data and the systems to which it is attributable. For example, the majority of energy billing is provided on a gross CV basis whereas transportation is based on a net CV basis. In other sources, gross and net CVs may be referred to as higher heating values or lower heating values respectively. What is the difference? - Gross calorific value (CV) or higher heating value (HHV) is the CV under laboratory conditions and is commonly utilised for the use of natural gas in heating and cooling systems. Net CV or lower heating value (LHV) is the useful calorific value in typical real world conditions (e.g. boiler plant or transportation). The difference is essentially the latent heat of the water vapour produced (which can be recovered in laboratory or sealed conditions).
A12: ● 'Diesel (average biofuel blend)'/'diesel (100% mineral oil)' - typically organisations purchasing forecourt fuel should use 'diesel (average biofuel blend)'. It should be noted that any fuel an organisation reports in Scope 1 that has biofuel content must have the ‘outside of scopes’ portion reported separately as per the 'WBCSD/WRI GHG Protocol (chapter 9)'. See information about the outside of scopes emissions in the example section below. ● In 2019 update, a new factor for natural gas, "natural gas (100% mineral blend)", was added in. The difference between the "natural gas" and "natural gas (100% mineral blend)" factors is that the former refers to the natural gas received through the gas mains grid network in the UK containing a limited biogas content. Therefore, any organisation that reports emissions from natural gas use should use the "natural gas" factor. The natural gas (100% mineral blend) factor can be used for calculating bespoke fuel mixtures.
A13: ● If any fuel type or unit has no result in the table, this is an indication the conversion factor is not available or does not exist. ● Users of the aviation turbine fuel factors may need to apply a 1.7 multiplier to the CO2 factor to account for the radiative forcing effects of emissions at altitude. Further explanation of this is provided in the Conversion Factors Methodology Paper.
A14: Example of calculating emissions from fuels
A15: Company A needs to report the Scope 1 emissions from its natural gas and diesel use.
A16: ● For natural gas consumption it selects a kWh conversion factor on a gross CV basis - this is the basis of most energy bills. It reports in CO2e for all fuels combusted at its premises.
A17: ● It is faced with two different types of diesel conversion factors, '100% mineral fuel' and 'diesel (average biofuel blend)'. Since it fills up its vehicles at a national chain of filling stations, it selects the average biofuel blend (this is the correct conversion factor for standard forecourt fuel, which contains a small blend of biofuel).
A18: The activity data (that is, litres) is multiplied by the appropriate conversion factor to produce company A's fuel emissions. Organisations should determine whether to use the net or gross calorific value of fuels according to their data and the systems to which it is attributable. For example, the majority of energy billing is provided on a gross CV basis whereas transportation is based on a net CV basis. In other sources, gross and net CVs may be referred to as higher heating values or lower heating values respectively.
A19: Since company A is reporting a type of fuel that has biofuel content, it should also account for the ‘biogenic’ part of this fuel. To calculate this, it must also multiply the total litres of fuel used by the ‘outside of scopes’ fuel factor for ‘forecourt fuels- diesel (average biofuel blend)’ and report as a separate line item within its report called ‘outside of scopes’. This will not be included in the organisation's emissions total, but displayed separately within the emissions report. This ensures that the organisation is being transparent with regard to all potential sources of CO2 from its activities.
A20: For more information refer to the ‘Outside of scopes’ tab for guidance.
A22: Activity | B22: Fuel | C22: Unit | D22: kg CO2e | E22: kg CO2e of CO2 per unit | F22: kg CO2e of CH4 per unit | G22: kg CO2e of N2O per unit
A23: Gaseous fuels | B23: Butane | C23: tonnes | D23: 3033.3807 | E23: 3029.26 | F23: 2.52 | G23: 1.60067
B24: Butane | C24: litres | D24: 1.74532 | E24: 1.74296 | F24: 0.00144 | G24: 0.00092
B25: Butane | C25: kWh (Net CV) | D25: 0.24106 | E25: 0.24074 | F25: 0.0002 | G25: 0.00012
B26: Butane | C26: kWh (Gross CV) | D26: 0.22241 | E26: 0.2221 | F26: 0.00019 | G26: 0.00012
B27: CNG | C27: tonnes | D27: 2568.1644 | E27: 2563.12 | F27: 3.8528 | G27: 1.19161
C28: litres | D28: 0.44942 | E28: 0.44855 | F28: 0.00067 | G28: 0.0002
C29: kWh (Net CV) | D29: 0.20264 | E29: 0.20223 | F29: 0.00031 | G29: 0.0001
C30: kWh (Gross CV) | D30: 0.1829 | E30: 0.18253 | F30: 0.00028 | G30: 9e-05
B31: LNG | C31: tonnes | D31: 2590.4644 | E31: 2585.42 | F31: 3.8528 | G31: 1.19161
C32: litres | D32: 1.17216 | E32: 1.16987 | F32: 0.00175 | G32: 0.00054
C33: kWh (Net CV) | D33: 0.2044 | E33: 0.20399 | F33: 0.00031 | G33: 0.0001
C34: kWh (Gross CV) | D34: 0.18449 | E34: 0.18412 | F34: 0.00028 | G34: 9e-05
B35: LPG | C35: tonnes | D35: 2939.3609 | E35: 2935.18 | F35: 2.5536 | G35: 1.62735
C36: litres | D36: 1.55713 | E36: 1.55491 | F36: 0.00136 | G36: 0.00086
C37: kWh (Net CV) | D37: 0.23031 | E37: 0.22999 | F37: 0.0002 | G37: 0.00012
C38: kWh (Gross CV) | D38: 0.2145 | E38: 0.21419 | F38: 0.00019 | G38: 0.00012
B39: Natural gas | C39: tonnes | D39: 2568.1644 | E39: 2563.12 | F39: 3.8528 | G39: 1.19161
C40: cubic metres | D40: 2.04542 | E40: 2.0414 | F40: 0.00307 | G40: 0.00095
C41: kWh (Net CV) | D41: 0.20264 | E41: 0.20223 | F41: 0.00031 | G41: 0.0001
C42: kWh (Gross CV) | D42: 0.1829 | E42: 0.18253 | F42: 0.00028 | G42: 9e-05
B43: Natural gas (100% mineral blend) | C43: tonnes | D43: 2590.4644 | E43: 2585.42 | F43: 3.8528 | G43: 1.19161
C44: cubic metres | D44: 2.06318 | E44: 2.05916 | F44: 0.00307 | G44: 0.00095
...

Sheet Fuels 25
A1: UK Government GHG Conversion Factors for Company Reporting
A2: Fuels
A3: Index
A5: Emissions source: | B5: Fuels | C5: Next publication date: | D5: June 2026 | E5: Factor set: | F5: Condensed set
A6: Scope: | B6: Scope 1 | C6: Version: | D6: 1 | E6: Year: | F6: 2025
A8: Fuels conversion factors should be used for primary fuel sources combusted at a site or in an asset owned or controlled by the reporting organisation.
A10: Guidance
A11: ● Gross calorific value (CV)/ net CV basis: - Organisations should determine whether to use the net or gross calorific value of fuels according to their data and the systems to which it is attributable. For example, the majority of energy billing is provided on a gross CV basis whereas transportation is based on a net CV basis. In other sources, gross and net CVs may be referred to as higher heating values or lower heating values respectively. What is the difference? - Gross calorific value (CV) or higher heating value (HHV) is the CV under laboratory conditions and is commonly utilised for the use of natural gas in heating and cooling systems. - Net CV or lower heating value (LHV) is the useful calorific value in typical real world conditions (e.g. boiler plant or transportation). The difference is essentially the latent heat of the water vapour produced (which can be recovered in laboratory or sealed conditions). It is recommended to apply a consistent calorific value (CV) basis across all energy sources. Where natural gas consumption data is available in kWh, using it directly can help to avoid conversion errors and decisions around CV basis. Where data is only available in cubic metres (m³), users may wish to use Net CV to convert to kWh for consistency with other factors in this set, many of which are only published on a Net CV basis.
A12: ● 'Diesel (average biofuel blend)'/'diesel (100% mineral oil)' - typically organisations purchasing forecourt fuel should use 'diesel (average biofuel blend)'. It should be noted that any fuel an organisation reports in Scope 1 that has biofuel content must have the ‘outside of scopes’ portion reported separately as per the 'WBCSD/WRI GHG Protocol (chapter 9)'. See information about the outside of scopes emissions in the example section below. ● In 2019 update, a new factor for natural gas, "natural gas (100% mineral blend)", was added in. The difference between the "natural gas" and "natural gas (100% mineral blend)" factors is that the former refers to the natural gas received through the gas mains grid network in the UK containing a limited biogas content. Therefore, any organisation that reports emissions from natural gas use should use the "natural gas" factor. The natural gas (100% mineral blend) factor can be used for calculating bespoke fuel mixtures.
A13: ● If any fuel type or unit has no result in the table, this is an indication the conversion factor is not available or does not exist. ● Users of the aviation turbine fuel or aviation spirit factors may need to apply a 1.7 multiplier to the CO2 factor to account for the radiative forcing effects of emissions at altitude. Further explanation of this is provided in the Conversion Factors Methodology Paper.
A14: Example of calculating emissions from fuels
A15: Company A needs to report the Scope 1 emissions from its natural gas and diesel use.
A16: ● For natural gas consumption it selects a kWh conversion factor on a gross CV basis - this is the basis of most energy bills. It reports in CO2e for all fuels combusted at its premises.
A17: ● It is faced with two different types of diesel conversion factors, '100% mineral fuel' and 'diesel (average biofuel blend)'. Since it fills up its vehicles at a national chain of filling stations, it selects the average biofuel blend (this is the correct conversion factor for standard forecourt fuel, which contains a small blend of biofuel).
A18: The activity data (that is, litres) is multiplied by the appropriate conversion factor to produce company A's fuel emissions. Organisations should determine whether to use the net or gross calorific value of fuels according to their data and the systems to which it is attributable. For example, the majority of energy billing is provided on a gross CV basis whereas transportation is based on a net CV basis. In other sources, gross and net CVs may be referred to as higher heating values or lower heating values respectively.
A19: Since company A is reporting a type of fuel that has biofuel content, it should also account for the ‘biogenic’ part of this fuel. To calculate this, it must also multiply the total litres of fuel used by the ‘outside of scopes’ fuel factor for ‘forecourt fuels- diesel (average biofuel blend)’ and report as a separate line item within its report called ‘outside of scopes’. This will not be included in the organisation's emissions total, but displayed separately within the emissions report. This ensures that the organisation is being transparent with regard to all potential sources of CO2 from its activities.
A20: For more information refer to the ‘Outside of scopes’ tab for guidance.
A22: Activity | B22: Fuel | C22: Unit | D22: kg CO2e | E22: kg CO2e of CO2 per unit | F22: kg CO2e of CH4 per unit | G22: kg CO2e of N2O per unit
A23: Gaseous fuels | B23: Butane | C23: tonnes | D23: 3033.3807 | E23: 3029.26 | F23: 2.52 | G23: 1.60067
B24: Butane | C24: litres | D24: 1.74533 | E24: 1.74296 | F24: 0.00144 | G24: 0.00092
B25: Butane | C25: kWh (Net CV) | D25: 0.24107 | E25: 0.24074 | F25: 0.0002 | G25: 0.00012
B26: Butane | C26: kWh (Gross CV) | D26: 0.22241 | E26: 0.2221 | F26: 0.00019 | G26: 0.00012
B27: CNG | C27: tonnes | D27: 2575.4644 | E27: 2570.42 | F27: 3.8528 | G27: 1.19161
C28: litres | D28: 0.4507 | E28: 0.44982 | F28: 0.00067 | G28: 0.0002
C29: kWh (Net CV) | D29: 0.2027 | E29: 0.20229 | F29: 0.00031 | G29: 0.0001
C30: kWh (Gross CV) | D30: 0.18296 | E30: 0.18259 | F30: 0.00028 | G30: 9e-05
B31: LNG | C31: tonnes | D31: 2603.3044 | E31: 2598.26 | F31: 3.8528 | G31: 1.19161
C32: litres | D32: 1.17797 | E32: 1.17568 | F32: 0.00175 | G32: 0.00054
C33: kWh (Net CV) | D33: 0.20489 | E33: 0.20448 | F33: 0.00031 | G33: 0.0001
C34: kWh (Gross CV) | D34: 0.18494 | E34: 0.18457 | F34: 0.00028 | G34: 9e-05
B35: LPG | C35: tonnes | D35: 2939.3609 | E35: 2935.18 | F35: 2.5536 | G35: 1.62735
C36: litres | D36: 1.55713 | E36: 1.55491 | F36: 0.00136 | G36: 0.00086
C37: kWh (Net CV) | D37: 0.23032 | E37: 0.22999 | F37: 0.0002 | G37: 0.00012
C38: kWh (Gross CV) | D38: 0.2145 | E38: 0.21419 | F38: 0.00019 | G38: 0.00012
B39: Natural gas | C39: tonnes | D39: 2575.4644 | E39: 2570.42 | F39: 3.8528 | G39: 1.19161
C40: cubic metres | D40: 2.06672 | E40: 2.0627 | F40: 0.00307 | G40: 0.00095
C41: kWh (Net CV) | D41: 0.2027 | E41: 0.20229 | F41: 0.00031 | G41: 0.0001
C42: kWh (Gross CV) | D42: 0.18296 | E42: 0.18259 | F42: 0.00028 | G42: 9e-05
B43: Natural gas (100% mineral blend) | C43: tonnes | D43: 2603.3044 | E43: 2598.26 | F43: 3.8528 | G43: 1.19161
C44: cubic metres | D44: 2.08906 | E44: 2.08504 | F44: 0.00307 | G44: 0.00095
...

Sheet UK electricity 23
A1: UK Government GHG Conversion Factors for Company Reporting
A2: UK electricity
A3: Index
A5: Emissions source: | B5: UK electricity | C5: Next publication date: | D5: 45453 | E5: Factor set: | F5: Condensed set
A6: Scope: | B6: Scope 2 | C6: Version: | D6: 1.1 | E6: Year: | F6: 2023
A8: UK electricity conversion factors should be used to report on electricity used by an organisation at sites owned/controlled by them. This is reported as a Scope 2, indirect emission. The conversion factors in this listing are for the electricity supplied to the grid that organisations purchase - they do not include the emissions associated with the transmission and distribution of electricity.
A10: Guidance
A11: ● The year displayed alongside the electricity factors is the reporting year for which users should apply these factors. This is based on a calendar reporting year.
A12: ● The Government's 'Environmental reporting guidelines' require that Scope 2 electricity emissions are reported using location-based grid average emissions factors. A market-based Scope 2 figure may optionally be reported but only in addition to the location-based figure. Market-based emissions reflect a contractual entitlement to claim an emissions rate, allowing for a reduced emission figure where, for example, a renewable energy tariff is backed by certificates to track attributes associated with energy generation. The location-based emissions reflect the average emission of the grid where the energy consumption occurs and is calculated using these UK Electricity grid average factors below. Organisations using a market-based figure may want to consider adding narrative information on whether their contractual arrangements cause additional renewable electricity generation.
A13: ● We advise that organisations also account for the transmission and distribution (T&D) losses of the electricity they purchase, which occur between the power station and their site(s). They should do so using the ‘transmission and distribution’ factors for UK electricity. The emissions from T&D should be accounted for in Scope 3.
A14: ● Organisations that generate renewable energy or purchase green energy should refer to chapter 2 of the Government's 'Environmental reporting guidelines' for information on how to account for their electricity use.
A15: ● If an organisation voluntarily reports the electricity used at a site/for an asset in its supply chain that is not directly under its ownership or control, it may report this electricity in Scope 3. A duplicate set of conversion factors have been provided for this purpose in the Scope 3 listing, under ‘managed assets- electricity’.
A17: Why has the electricity factor changed?
A18: The UK electricity factor is prone to fluctuate from year to year as the fuel mix consumed in UK power stations (and auto-generators) and the proportion of net imported electricity changes. These annual changes can be large as the factor depends very heavily on the relative prices of coal and natural gas as well as fluctuations in peak demand and renewables. Given the importance of this factor, the explanation for fluctuations will be presented here henceforth. In the 2019 GHG Conversion Factors, there was a 10% decrease in the UK Electricity CO2e factor compared to the previous year. In the 2020 update, the CO2e factor decreased (compared with 2019) again by 9%. In the 2021 update, the CO2e factor again decreased by 9% (in comparison to the 2020 update). The above decreases are all due to a decrease in coal use in electricity generation and an increase in renewable generation. In the 2023 update, the UK Electricity CO2e factor has increased by 7% (compared to the 2022 update) due to an increase in natural gas use in electricity generation and a decrease in renewable generation.
A19: Example of calculating emissions from UK electricity
A20: Company G reports the emissions from the electricity it uses, which can be found by reading its electricity meters or gathering data from utility bills.
A21: The kWh electricity use is multiplied by the ‘electricity generated’ figure appropriate to the reporting year to produce company G's UK Scope 2 electricity emissions.
A23: Activity | B23: Country | C23: Unit | D23: Year | E23: kg CO2e | F23: kg CO2e of CO2 per unit | G23: kg CO2e of CH4 per unit | H23: kg CO2e of N2O per unit
A24: Electricity generated | B24: Electricity: UK | C24: kWh | D24: 2023 | E24: 0.20707429 | F24: 0.20496 | G24: 0.000896 | H24: 0.0012182886
A27: FAQs
A28: I am not publishing a company report, but I need a factor for ‘electricity consumption’ instead of ‘electricity generation’ what should I do?
A29: For company reporting purposes, organisations should use the ‘electricity generation’ figures for Scope 2 electricity and may use the ‘T&D’ factors found in the 'Transmission and distribution' tab for reporting Scope 3 losses. However, for other reporting contexts (where specific scopes do not need to be reported) the ‘electricity consumption’ figure can be calculated by adding together the ‘electricity generation’ and the ‘T&D’ values within each year.
A30: I previously used a 5-year grid rolling average factors. These factors are based on 1-year average factors and look quite different, what should I do?
A31: Please refer to the 'What's new in 2013' section of the ‘What’s new’ tab of the 2013 GHG Conversion factors spreadsheet for full instructions on how to rebaseline your data to compensate for the changes made.
A32: For information about how the conversion factors have been derived, please refer to the 'Methodology paper' that accompanies the conversion factors.

Sheet UK electricity 24
A1: UK Government GHG Conversion Factors for Company Reporting
A2: UK electricity
A3: Index
A5: Emissions source: | B5: UK electricity | C5: Next publication date: | D5: 45818 | E5: Factor set: | F5: Condensed set
A6: Scope: | B6: Scope 2 | C6: Version: | D6: 1.1 | E6: Year: | F6: 2024
A8: UK electricity conversion factors should be used to report on electricity used by an organisation at sites owned/controlled by them. This is reported as a Scope 2, indirect emission. The conversion factors in this listing are for the electricity supplied to the grid that organisations purchase - they do not include the emissions associated with the transmission and distribution of electricity.
A10: Guidance
A11: ● The year displayed alongside the electricity factors is the reporting year for which users should apply these factors. This is based on a calendar reporting year.
A12: ● The Government's 'Environmental reporting guidelines' require that Scope 2 electricity emissions are reported using location-based grid average emissions factors. A market-based Scope 2 figure may optionally be reported but only in addition to the location-based figure. Market-based emissions reflect a contractual entitlement to claim an emissions rate, allowing for a reduced emission figure where, for example, a renewable energy tariff is backed by certificates to track attributes associated with energy generation. The location-based emissions reflect the average emission of the grid where the energy consumption occurs and is calculated using these UK Electricity grid average factors below. Organisations using a market-based figure may want to consider adding narrative information on whether their contractual arrangements cause additional renewable electricity generation.
A13: ● We advise that organisations also account for the transmission and distribution (T&D) losses of the electricity they purchase, which occur between the power station and their site(s). They should do so using the ‘transmission and distribution’ factors for UK electricity. The emissions from T&D should be accounted for in Scope 3.
A14: ● Organisations that generate renewable energy or purchase green energy should refer to chapter 2 of the Government's 'Environmental reporting guidelines' for information on how to account for their electricity use.
A15: ● If an organisation voluntarily reports the electricity used at a site/for an asset in its supply chain that is not directly under its ownership or control, it may report this electricity in Scope 3. A duplicate set of conversion factors have been provided for this purpose in the Scope 3 listing, under ‘managed assets- electricity’.
A16: ● Where electricity is onsite generated from a renewable source such as PV then the kWh should be reported under scope 1 with 0 emissions for both the electricity fuel source and 0 emissions for the T&D value.
A18: Why has the electricity factor changed?
A19: The UK electricity factor is prone to fluctuate from year to year as the fuel mix consumed in UK power stations (and auto-generators) and the proportion of net imported electricity changes. These annual changes can be large as the factor depends very heavily on the relative prices of coal and natural gas as well as fluctuations in peak demand and renewables. Given the importance of this factor, the explanation for fluctuations will be presented here henceforth. In the 2019 GHG Conversion Factors, there was a 10% decrease in the UK Electricity CO2e factor compared to the previous year. In the 2020 update, the CO2e factor decreased (compared with 2019) again by 9%. In the 2021 update, the CO2e factor again decreased by 9% (in comparison to the 2020 update). The above decreases are all due to a decrease in coal use in electricity generation and an increase in renewable generation. In the 2024 update, the UK Electricity CO2e factor has remained at a similar level to 2023 update.
A20: Example of calculating emissions from UK electricity
A21: Company G reports the emissions from the electricity it uses, which can be found by reading its electricity meters or gathering data from utility bills.
A22: The kWh electricity use is multiplied by the ‘electricity generated’ figure appropriate to the reporting year to produce company G's UK Scope 2 electricity emissions.
A24: Activity | B24: Country | C24: Unit | D24: Year | E24: kg CO2e | F24: kg CO2e of CO2 per unit | G24: kg CO2e of CH4 per unit | H24: kg CO2e of N2O per unit
A25: Electricity generated | B25: Electricity: UK | C25: kWh | D25: 2024 | E25: 0.20705 | F25: 0.20493 | G25: 0.0009 | H25: 0.00122
A28: FAQs
A29: I am not publishing a company report, but I need a factor for ‘electricity consumption’ instead of ‘electricity generation’ what should I do?
A30: For company reporting purposes, organisations should use the ‘electricity generation’ figures for Scope 2 electricity and may use the ‘T&D’ factors found in the 'Transmission and distribution' tab for reporting Scope 3 losses. However, for other reporting contexts (where specific scopes do not need to be reported) the ‘electricity consumption’ figure can be calculated by adding together the ‘electricity generation’ and the ‘T&D’ values within each year.
A31: I previously used a 5-year grid rolling average factors. These factors are based on 1-year average factors and look quite different, what should I do?
A32: Please refer to the 'What's new in 2013' section of the ‘What’s new’ tab of the 2013 GHG Conversion factors spreadsheet for full instructions on how to rebaseline your data to compensate for the changes made.
A33: For information about how the conversion factors have been derived, please refer to the 'Methodology paper' that accompanies the conversion factors.

Sheet UK electricity 25
A1: UK Government GHG Conversion Factors for Company Reporting
A2: UK electricity
A3: Index
A5: Emissions source: | B5: UK electricity | C5: Next publication date: | D5: June 2026 | E5: Factor set: | F5: Condensed set
A6: Scope: | B6: Scope 2 | C6: Version: | D6: 1 | E6: Year: | F6: 2025
A8: UK electricity conversion factors should be used to report on electricity used by an organisation at sites owned/controlled by them. This is reported as a Scope 2, indirect emission. The conversion factors in this listing are for the electricity supplied to the grid that organisations purchase - they do not include the emissions associated with the transmission and distribution of electricity.
A10: Guidance
A11: ● The year displayed alongside the electricity factors is the reporting year for which users should apply these factors. This is based on a calendar reporting year.
A12: ● The Government's 'Environmental reporting guidelines' require that Scope 2 electricity emissions are reported using location-based grid average emissions factors. A market-based Scope 2 figure may optionally be reported but only in addition to the location-based figure. Market-based emissions reflect a contractual entitlement to claim an emissions rate, allowing for a reduced emission figure where, for example, a renewable energy tariff is backed by certificates to track attributes associated with energy generation. The location-based emissions reflect the average emission of the grid where the energy consumption occurs and is calculated using these UK Electricity grid average factors below. Organisations using a market-based figure may want to consider adding narrative information on whether their contractual arrangements cause additional renewable electricity generation.
A13: ● We advise that organisations also account for the transmission and distribution (T&D) losses of the electricity they purchase, which occur between the power station and their site(s). They should do so using the ‘transmission and distribution’ factors for UK electricity. The emissions from T&D should be accounted for in Scope 3.
A14: ● Organisations that generate renewable energy or purchase green energy should refer to chapter 2 of the Government's 'Environmental reporting guidelines' for information on how to account for their electricity use.
A15: ● If an organisation voluntarily reports the electricity used at a site/for an asset in its supply chain that is not directly under its ownership or control, it may report this electricity in Scope 3. A duplicate set of conversion factors have been provided for this purpose in the Scope 3 listing, under ‘managed assets- electricity’.
A16: ● Where electricity is onsite generated from a renewable source such as PV then the kWh should be reported under scope 1 with 0 emissions for both the electricity fuel source and 0 emissions for the T&D value.
A17: ● Organisations seeking to account for the biogenic CO2 emissions of the electricity they purchase, which come from the combustion of biomass in power stations, should do so using the 'Outside of Scopes' factor for UK electricity.
A19: Why has the electricity factor changed?
A20: The UK electricity factor is prone to fluctuate from year to year as the fuel mix consumed in UK power stations (and auto-generators) and the proportion of net imported electricity changes. These annual changes can be large as the factor depends very heavily on the relative prices of coal and natural gas as well as fluctuations in peak demand and renewables. Given the importance of this factor, the explanation for fluctuations will be presented here henceforth. In the 2019 GHG Conversion Factors, there was a 10% decrease in the UK Electricity CO2e factor compared to the previous year. In the 2020 update, the CO2e factor decreased (compared with 2019) again by 9%. In the 2021 update, the CO2e factor again decreased by 9% (in comparison to the 2020 update). The above decreases are all due to a decrease in coal use in electricity generation and an increase in renewable generation. In the 2025 update, the UK Electricity CO2e factor has reduced by approximately 15% since 2024. The decrease is due to less natural gas use in power stations, an increase in renewable energy, and an increase in net imports of relatively low carbon electricity.
A21: Example of calculating emissions from UK electricity
... A23: The kWh electricity use is multiplied by the ‘electricity generated’ figure appropriate to the reporting year to produce company G's UK Scope 2 electricity emissions.
A25: Activity | B25: Country | C25: Unit | D25: Year | E25: kg CO2e | F25: kg CO2e of CO2 per unit | G25: kg CO2e of CH4 per unit | H25: kg CO2e of N2O per unit
A26: Electricity generated | B26: Electricity: UK | C26: kWh | D26: 2025 | E26: 0.177 | F26: 0.17489 | G26: 0.0009 | H26: 0.00122
A29: FAQs
A30: I am not publishing a company report, but I need a factor for ‘electricity consumption’ instead of ‘electricity generation’ what should I do?
A31: For company reporting purposes, organisations should use the ‘electricity generation’ figures for Scope 2 electricity and may use the ‘T&D’ factors found in the 'Transmission and distribution' tab for reporting Scope 3 losses. However, for other reporting contexts (where specific scopes do not need to be reported) the ‘electricity consumption’ figure can be calculated by adding together the ‘electricity generation’ and the ‘T&D’ values within each year.
